[2024-09-22T16:59:01.104+0000] {local_task_job_runner.py:123} INFO - ::group::Pre task execution logs
[2024-09-22T16:59:01.129+0000] {taskinstance.py:2603} INFO - Dependencies all met for dep_context=non-requeueable deps ti=<TaskInstance: emp_dag.emp_data_load scheduled__2024-09-21T00:00:00+00:00 [queued]>
[2024-09-22T16:59:01.140+0000] {taskinstance.py:2603} INFO - Dependencies all met for dep_context=requeueable deps ti=<TaskInstance: emp_dag.emp_data_load scheduled__2024-09-21T00:00:00+00:00 [queued]>
[2024-09-22T16:59:01.141+0000] {taskinstance.py:2856} INFO - Starting attempt 2 of 2
[2024-09-22T16:59:01.161+0000] {taskinstance.py:2879} INFO - Executing <Task(BashOperator): emp_data_load> on 2024-09-21 00:00:00+00:00
[2024-09-22T16:59:01.172+0000] {warnings.py:112} WARNING - /home/***/.local/lib/python3.12/site-packages/***/task/task_runner/standard_task_runner.py:70: DeprecationWarning: This process (pid=357) is multi-threaded, use of fork() may lead to deadlocks in the child.
  pid = os.fork()

[2024-09-22T16:59:01.174+0000] {standard_task_runner.py:72} INFO - Started process 359 to run task
[2024-09-22T16:59:01.175+0000] {standard_task_runner.py:104} INFO - Running: ['***', 'tasks', 'run', 'emp_dag', 'emp_data_load', 'scheduled__2024-09-21T00:00:00+00:00', '--job-id', '7', '--raw', '--subdir', 'DAGS_FOLDER/emp_dag.py', '--cfg-path', '/tmp/tmpjrqond0e']
[2024-09-22T16:59:01.177+0000] {standard_task_runner.py:105} INFO - Job 7: Subtask emp_data_load
[2024-09-22T16:59:01.250+0000] {task_command.py:467} INFO - Running <TaskInstance: emp_dag.emp_data_load scheduled__2024-09-21T00:00:00+00:00 [running]> on host 3ac4fa004d82
[2024-09-22T16:59:01.366+0000] {taskinstance.py:3122} INFO - Exporting env vars: AIRFLOW_CTX_DAG_OWNER='***_SS' AIRFLOW_CTX_DAG_ID='emp_dag' AIRFLOW_CTX_TASK_ID='emp_data_load' AIRFLOW_CTX_EXECUTION_DATE='2024-09-21T00:00:00+00:00' AIRFLOW_CTX_TRY_NUMBER='2' AIRFLOW_CTX_DAG_RUN_ID='scheduled__2024-09-21T00:00:00+00:00'
[2024-09-22T16:59:01.368+0000] {logging_mixin.py:190} INFO - Task instance is in running state
[2024-09-22T16:59:01.369+0000] {logging_mixin.py:190} INFO -  Previous state of the Task instance: queued
[2024-09-22T16:59:01.370+0000] {logging_mixin.py:190} INFO - Current task name:emp_data_load state:running start_date:2024-09-22 16:59:01.130048+00:00
[2024-09-22T16:59:01.370+0000] {logging_mixin.py:190} INFO - Dag name:emp_dag and current dag run status:running
[2024-09-22T16:59:01.371+0000] {taskinstance.py:731} INFO - ::endgroup::
[2024-09-22T16:59:01.373+0000] {subprocess.py:63} INFO - Tmp dir root location: /tmp
[2024-09-22T16:59:01.374+0000] {subprocess.py:75} INFO - Running command: ['/usr/bin/bash', '-c', 'python3 /opt/***/beam_scripts/emp_data_load.py']
[2024-09-22T16:59:01.392+0000] {subprocess.py:86} INFO - Output:
[2024-09-22T16:59:07.187+0000] {subprocess.py:93} INFO - Service account key path set to: /opt/***/cred/gcp-test.json
[2024-09-22T16:59:07.188+0000] {subprocess.py:93} INFO - Traceback (most recent call last):
[2024-09-22T16:59:07.190+0000] {subprocess.py:93} INFO -   File "/opt/***/beam_scripts/emp_data_load.py", line 134, in <module>
[2024-09-22T16:59:07.191+0000] {subprocess.py:93} INFO -     hello_pubsub()
[2024-09-22T16:59:07.192+0000] {subprocess.py:93} INFO -   File "/opt/***/beam_scripts/emp_data_load.py", line 99, in hello_pubsub
[2024-09-22T16:59:07.196+0000] {subprocess.py:93} INFO -     client = storage.Client(project=project_id)
[2024-09-22T16:59:07.197+0000] {subprocess.py:93} INFO -              ^^^^^^^^^^^^^^^^^^^^^^^^^^^^^^^^^^
[2024-09-22T16:59:07.197+0000] {subprocess.py:93} INFO -   File "/home/***/.local/lib/python3.12/site-packages/google/cloud/storage/client.py", line 227, in __init__
[2024-09-22T16:59:07.198+0000] {subprocess.py:93} INFO -     super(Client, self).__init__(
[2024-09-22T16:59:07.199+0000] {subprocess.py:93} INFO -   File "/home/***/.local/lib/python3.12/site-packages/google/cloud/client/__init__.py", line 321, in __init__
[2024-09-22T16:59:07.200+0000] {subprocess.py:93} INFO -     Client.__init__(
[2024-09-22T16:59:07.201+0000] {subprocess.py:93} INFO -   File "/home/***/.local/lib/python3.12/site-packages/google/cloud/client/__init__.py", line 178, in __init__
[2024-09-22T16:59:07.202+0000] {subprocess.py:93} INFO -     credentials, _ = google.auth.default(scopes=scopes)
[2024-09-22T16:59:07.203+0000] {subprocess.py:93} INFO -                      ^^^^^^^^^^^^^^^^^^^^^^^^^^^^^^^^^^
[2024-09-22T16:59:07.203+0000] {subprocess.py:93} INFO -   File "/home/***/.local/lib/python3.12/site-packages/google/auth/_default.py", line 657, in default
[2024-09-22T16:59:07.204+0000] {subprocess.py:93} INFO -     credentials, project_id = checker()
[2024-09-22T16:59:07.205+0000] {subprocess.py:93} INFO -                               ^^^^^^^^^
[2024-09-22T16:59:07.206+0000] {subprocess.py:93} INFO -   File "/home/***/.local/lib/python3.12/site-packages/google/auth/_default.py", line 650, in <lambda>
[2024-09-22T16:59:07.206+0000] {subprocess.py:93} INFO -     lambda: _get_explicit_environ_credentials(quota_project_id=quota_project_id),
[2024-09-22T16:59:07.207+0000] {subprocess.py:93} INFO -             ^^^^^^^^^^^^^^^^^^^^^^^^^^^^^^^^^^^^^^^^^^^^^^^^^^^^^^^^^^^^^^^^^^^^
[2024-09-22T16:59:07.208+0000] {subprocess.py:93} INFO -   File "/home/***/.local/lib/python3.12/site-packages/google/auth/_default.py", line 270, in _get_explicit_environ_credentials
[2024-09-22T16:59:07.209+0000] {subprocess.py:93} INFO -     credentials, project_id = load_credentials_from_file(
[2024-09-22T16:59:07.210+0000] {subprocess.py:93} INFO -                               ^^^^^^^^^^^^^^^^^^^^^^^^^^^
[2024-09-22T16:59:07.211+0000] {subprocess.py:93} INFO -   File "/home/***/.local/lib/python3.12/site-packages/google/auth/_default.py", line 114, in load_credentials_from_file
[2024-09-22T16:59:07.212+0000] {subprocess.py:93} INFO -     raise exceptions.DefaultCredentialsError(
[2024-09-22T16:59:07.213+0000] {subprocess.py:93} INFO - google.auth.exceptions.DefaultCredentialsError: File /opt/***/cred/gcp-test.json was not found.
[2024-09-22T16:59:07.801+0000] {subprocess.py:97} INFO - Command exited with return code 1
[2024-09-22T16:59:07.827+0000] {taskinstance.py:3301} ERROR - Task failed with exception
Traceback (most recent call last):
  File "/home/airflow/.local/lib/python3.12/site-packages/airflow/models/taskinstance.py", line 767, in _execute_task
    result = _execute_callable(context=context, **execute_callable_kwargs)
             ^^^^^^^^^^^^^^^^^^^^^^^^^^^^^^^^^^^^^^^^^^^^^^^^^^^^^^^^^^^^^
  File "/home/airflow/.local/lib/python3.12/site-packages/airflow/models/taskinstance.py", line 733, in _execute_callable
    return ExecutionCallableRunner(
           ^^^^^^^^^^^^^^^^^^^^^^^^
  File "/home/airflow/.local/lib/python3.12/site-packages/airflow/utils/operator_helpers.py", line 252, in run
    return self.func(*args, **kwargs)
           ^^^^^^^^^^^^^^^^^^^^^^^^^^
  File "/home/airflow/.local/lib/python3.12/site-packages/airflow/models/baseoperator.py", line 406, in wrapper
    return func(self, *args, **kwargs)
           ^^^^^^^^^^^^^^^^^^^^^^^^^^^
  File "/home/airflow/.local/lib/python3.12/site-packages/airflow/operators/bash.py", line 249, in execute
    raise AirflowException(
airflow.exceptions.AirflowException: Bash command failed. The command returned a non-zero exit code 1.
[2024-09-22T16:59:07.837+0000] {logging_mixin.py:190} INFO - Task instance in failure state
[2024-09-22T16:59:07.839+0000] {logging_mixin.py:190} INFO - Task start:2024-09-22 16:59:01.130048+00:00 end:2024-09-22 16:59:07.835982+00:00 duration:6.705934
[2024-09-22T16:59:07.841+0000] {logging_mixin.py:190} INFO - Task:<Task(BashOperator): emp_data_load> dag:<DAG: emp_dag> dagrun:<DagRun emp_dag @ 2024-09-21 00:00:00+00:00: scheduled__2024-09-21T00:00:00+00:00, state:running, queued_at: 2024-09-22 16:52:35.626655+00:00. externally triggered: False>
[2024-09-22T16:59:07.842+0000] {logging_mixin.py:190} INFO - Failure caused by Bash command failed. The command returned a non-zero exit code 1.
[2024-09-22T16:59:07.844+0000] {taskinstance.py:1225} INFO - Marking task as FAILED. dag_id=emp_dag, task_id=emp_data_load, run_id=scheduled__2024-09-21T00:00:00+00:00, execution_date=20240921T000000, start_date=20240922T165901, end_date=20240922T165907
[2024-09-22T16:59:07.884+0000] {taskinstance.py:340} INFO - ::group::Post task execution logs
[2024-09-22T16:59:07.886+0000] {standard_task_runner.py:124} ERROR - Failed to execute job 7 for task emp_data_load (Bash command failed. The command returned a non-zero exit code 1.; 359)
Traceback (most recent call last):
  File "/home/airflow/.local/lib/python3.12/site-packages/airflow/task/task_runner/standard_task_runner.py", line 117, in _start_by_fork
    ret = args.func(args, dag=self.dag)
          ^^^^^^^^^^^^^^^^^^^^^^^^^^^^^
  File "/home/airflow/.local/lib/python3.12/site-packages/airflow/cli/cli_config.py", line 49, in command
    return func(*args, **kwargs)
           ^^^^^^^^^^^^^^^^^^^^^
  File "/home/airflow/.local/lib/python3.12/site-packages/airflow/utils/cli.py", line 115, in wrapper
    return f(*args, **kwargs)
           ^^^^^^^^^^^^^^^^^^
  File "/home/airflow/.local/lib/python3.12/site-packages/airflow/cli/commands/task_command.py", line 483, in task_run
    task_return_code = _run_task_by_selected_method(args, _dag, ti)
                       ^^^^^^^^^^^^^^^^^^^^^^^^^^^^^^^^^^^^^^^^^^^^
  File "/home/airflow/.local/lib/python3.12/site-packages/airflow/cli/commands/task_command.py", line 256, in _run_task_by_selected_method
    return _run_raw_task(args, ti)
           ^^^^^^^^^^^^^^^^^^^^^^^
  File "/home/airflow/.local/lib/python3.12/site-packages/airflow/cli/commands/task_command.py", line 341, in _run_raw_task
    return ti._run_raw_task(
           ^^^^^^^^^^^^^^^^^
  File "/home/airflow/.local/lib/python3.12/site-packages/airflow/utils/session.py", line 97, in wrapper
    return func(*args, session=session, **kwargs)
           ^^^^^^^^^^^^^^^^^^^^^^^^^^^^^^^^^^^^^^
  File "/home/airflow/.local/lib/python3.12/site-packages/airflow/models/taskinstance.py", line 2995, in _run_raw_task
    return _run_raw_task(
           ^^^^^^^^^^^^^^
  File "/home/airflow/.local/lib/python3.12/site-packages/airflow/models/taskinstance.py", line 273, in _run_raw_task
    TaskInstance._execute_task_with_callbacks(
  File "/home/airflow/.local/lib/python3.12/site-packages/airflow/models/taskinstance.py", line 3149, in _execute_task_with_callbacks
    result = self._execute_task(context, task_orig)
             ^^^^^^^^^^^^^^^^^^^^^^^^^^^^^^^^^^^^^^
  File "/home/airflow/.local/lib/python3.12/site-packages/airflow/models/taskinstance.py", line 3173, in _execute_task
    return _execute_task(self, context, task_orig)
           ^^^^^^^^^^^^^^^^^^^^^^^^^^^^^^^^^^^^^^^
  File "/home/airflow/.local/lib/python3.12/site-packages/airflow/models/taskinstance.py", line 767, in _execute_task
    result = _execute_callable(context=context, **execute_callable_kwargs)
             ^^^^^^^^^^^^^^^^^^^^^^^^^^^^^^^^^^^^^^^^^^^^^^^^^^^^^^^^^^^^^
  File "/home/airflow/.local/lib/python3.12/site-packages/airflow/models/taskinstance.py", line 733, in _execute_callable
    return ExecutionCallableRunner(
           ^^^^^^^^^^^^^^^^^^^^^^^^
  File "/home/airflow/.local/lib/python3.12/site-packages/airflow/utils/operator_helpers.py", line 252, in run
    return self.func(*args, **kwargs)
           ^^^^^^^^^^^^^^^^^^^^^^^^^^
  File "/home/airflow/.local/lib/python3.12/site-packages/airflow/models/baseoperator.py", line 406, in wrapper
    return func(self, *args, **kwargs)
           ^^^^^^^^^^^^^^^^^^^^^^^^^^^
  File "/home/airflow/.local/lib/python3.12/site-packages/airflow/operators/bash.py", line 249, in execute
    raise AirflowException(
airflow.exceptions.AirflowException: Bash command failed. The command returned a non-zero exit code 1.
[2024-09-22T16:59:07.931+0000] {local_task_job_runner.py:261} INFO - Task exited with return code 1
[2024-09-22T16:59:07.975+0000] {taskinstance.py:3891} INFO - 0 downstream tasks scheduled from follow-on schedule check
[2024-09-22T16:59:07.980+0000] {local_task_job_runner.py:240} INFO - ::endgroup::
